Workbook

Sheet Sheet1
A1: 프로젝트 개요
A2: 프로젝트명 | C2: ABCD (Auto Building Care Diagnostics) | I2: 주요기능 | L2: 1. 데이터 현황 관측 2. 알림 시스템으로 즉각적인 처리 가능 3. 간편한 조작으로 인한 쉬운 관리 4. 데이터 내역 관리
A3: 목적 | C3: 건물 관리 자동화 및 간편한 보수 유지
A4: 총 개발 기간 | C4: 11월 17일 - 12월 12일
A5: 팀장 | C5: 주총민 | D5: 디자인 | E5: 박승찬 | F5: FE | G5: 이예준 ,전서영 | J5: 테스터 | L5: 2조
A6: WBS 번호 | B6: 항목 | C6: 세부작업 | D6: 담당 | E6: 시작일 | F6: 종료일 | G6: 작업 기간 | H6: 진행 사항 | I6: 45962 | Z6: 45992 | AT6: =AU7 -> 30 | BP6: =BQ7 -> 60 | CH6: =CM7 -> 90 | DB6: =DH7 -> 121 | DY6: =EE7 -> 152 | ES6: =EZ7 -> 181 | FO6: =FV7 -> 213 | GG6: =GS7 -> 244 | HA6: =HM7 -> 272
I7: =WORKDAY(I6,1) -> 45964 | J7: =WORKDAY(I7,1,Sheet2!$A$3:$B$25) -> 45965 | K7: =WORKDAY(J7,1,Sheet2!$A$3:$B$25) -> 45966 | L7: =WORKDAY(K7,1,Sheet2!$A$3:$B$25) -> 45967 | M7: =WORKDAY(L7,1,Sheet2!$A$3:$B$25) -> 45968 | N7: 13 | O7: 14 | P7: 17 | Q7: =WORKDAY(P7,1,Sheet2!$A$3:$B$25) -> 18 | R7: =WORKDAY(Q7,1,Sheet2!$A$3:$B$25) -> 19 | S7: =WORKDAY(R7,1,Sheet2!$A$3:$B$25) -> 20 | T7: 21 | U7: 24 | V7: =WORKDAY(U7,1,Sheet2!$A$3:$B$25) -> 25 | W7: =WORKDAY(V7,1,Sheet2!$A$3:$B$25) -> 26 | X7: =WORKDAY(W7,1,Sheet2!$A$3:$B$25) -> 27 | Y7: 28 | Z7: 1 | AA7: =WORKDAY(Z7,1,Sheet2!$A$3:$B$25) -> 2 | AB7: =WORKDAY(AA7,1,Sheet2!$A$3:$B$25) -> 3 | AC7: =WORKDAY(AB7,1,Sheet2!$A$3:$B$25) -> 4 | AD7: =WORKDAY(AC7,1,Sheet2!$A$3:$B$25) -> 5 | AE7: 8 | AF7: =WORKDAY(AE7,1,Sheet2!$A$3:$B$25) -> 9 | AG7: =WORKDAY(AF7,1,Sheet2!$A$3:$B$25) -> 10 | AH7: =WORKDAY(AG7,1,Sheet2!$A$3:$B$25) -> 11 | AI7: 12 | AJ7: 15 | AK7: 16 | AL7: 17 | AM7: 18 | AN7: 19 | AO7: 22 | AP7: =WORKDAY(AO7,1,Sheet2!$A$3:$B$25) -> 23 | AQ7: =WORKDAY(AP7,1,Sheet2!$A$3:$B$25) -> 24 | AR7: =WORKDAY(AQ7,1,Sheet2!$A$3:$B$25) -> 25 | AS7: =WORKDAY(AR7,1,Sheet2!$A$3:$B$25) -> 26 | AT7: =WORKDAY(AS7,1,Sheet2!$A$3:$B$25) -> 27 | AU7: =WORKDAY(AT7,1,Sheet2!$A$3:$B$25) -> 30 | AV7: =WORKDAY(AU7,1,Sheet2!$A$3:$B$25) -> 31 | AW7: =WORKDAY(AV7,1,Sheet2!$A$3:$B$25) -> 32 | ... HV7: =WORKDAY(HU7,1,Sheet2!$A$3:$B$25) -> 285
I8: =I7 -> 45964 | J8: =J7 -> 45965 | K8: =K7 -> 45966 | L8: =L7 -> 45967 | M8: =M7 -> 45968 | N8: 목 | O8: 금 | P8: 월 | Q8: 화 | R8: 수 | S8: 목 | T8: 금 | U8: 월 | V8: 화 | W8: 수 | X8: 목 | Y8: 금 | Z8: 월 | AA8: 화 | AB8: 수 | AC8: 목 | AD8: 금 | AE8: 월 | AF8: 화 | AG8: 수 | AH8: 목 | AI8: 금 | AJ8: 월 | AK8: 화 | AL8: 수 | AM8: 목 | AN8: 금 | AO8: 월 | AP8: 화 | AQ8: 수 | AR8: 목 | AS8: 금 | AT8: 월 | AU8: 화 | AV8: 수 | AW8: 목 | AX8: 금 | AY8: =AY7 -> 34 | AZ8: =AZ7 -> 37 | BA8: =BA7 -> 38 | BB8: =BB7 -> 39 | BC8: =BC7 -> 40 | BD8: =BD7 -> 41 | BE8: =BE7 -> 44 | BF8: =BF7 -> 45 | ... HV8: =HV7 -> 285
A9: 1 | B9: 요구사항 분석 | C9: 프로젝트 목표 및 범위 정의 | D9: 2조 | E9: 11월 5일 | F9: 11월 11일 | G9: 5일 | H9: 완료
A10: 1.1 | C10: 사용자 요구사항 수집 및 분석 | D10: 2조 | E10: 11월 17일 | F10: 11월 20일 | G10: 4일 | H10: 진행중
A11: 1.2 | C11: 요구사항 문서 작성 및 검토 | D11: 주총민 | E11: 11월 18일 | F11: 11월 20일 | G11: 3일 | H11: 진행중
A12: 2 | B12: 기획 및 설계 | C12: 프로젝트 일정 수립 및 자원 할당 | D12: 2조 | E12: 11월 17일 | F12: 11월 18일 | G12: 2일 | H12: 완료
A13: 2.2 | C13: 기술 스택 결정 | D13: 2조 | E13: 11월 17일 | F13: 11월 18일 | G13: 2일 | H13: 완료
A14: 3 | B14: 설계 단계 | C14: Login (로그인) | D14: 2조 | E14: 11월 14일 | F14: 11월 19일 | G14: 1일 | H14: 진행중
A15: 3.1 | C15: Main (메인페이지) | D15: 2조 | E15: 11월 14일 | F15: 11월 19일 | G15: 1일 | H15: 진행중
A16: 3.2 | C16: Alarm (우측 알림내역) | D16: 2조 | E16: 11월 14일 | F16: 11월 19일 | G16: 1일 | H16: 진행중
A17: 3.3 | C17: Floors (건물 보기 페이지) | D17: 2조 | E17: 11월 14일 | F17: 11월 19일 | G17: 1일 | H17: 진행중
A18: 3.41 | C18: ElecData (전력 현황 페이지) | D18: 2조 | E18: 11월 14일 | F18: 11월 19일 | G18: 1일 | H18: 진행중
A19: 3.42 | C19: GasData (가스 현황 페이지) | D19: 2조 | E19: 11월 14일 | F19: 11월 19일 | G19: 1일 | H19: 진행중
A20: 3.43 | C20: WaterData (수도 현황 페이지) | D20: 2조 | E20: 11월 14일 | F20: 11월 19일 | G20: 1일 | H20: 진행중
A21: 3.44 | C21: TempData (온도 현황 페이지) | D21: 2조 | E21: 11월 14일 | F21: 11월 19일 | G21: 1일 | H21: 진행중
A22: 3.5 | C22: Problems (문제 내역 페이지) | D22: 2조 | E22: 11월 14일 | F22: 11월 19일 | G22: 1일 | H22: 진행중
A23: 3.6 | C23: Log (기록 페이지) | D23: 2조 | E23: 11월 14일 | F23: 11월 19일 | G23: 1일 | H23: 진행중
A24: 3.7 | C24: Admin (건물 관리자 페이지) | D24: 2조 | E24: 11월 14일 | F24: 11월 19일 | G24: 3일 | H24: 진행중
A25: 3.8 | C25: Master (사이트 관리자 페이지) | D25: 2조 | E25: 11월 14일 | F25: 11월 19일 | G25: 3일 | H25: 진행중
A26: 3.9 | C26: UI/UX 와이어프레임 및 프로토타입 생성 | D26: 박승찬 | E26: 11월 19일 | F26: 11월 24일 | G26: 4일 | H26: 예정
A27: 4 | B27: 개발 환경 설정 | C27: Git 및 코드 관리 시스템 설정 | D27: 이예준 | E27: 11월 20일 | F27: 11월 24일 | G27: 3일 | H27: 예정
A28: 4.1 | C28: 개발 환경 설정 | D28: 이예준 | E28: 11월 20일 | F28: 11월 24일 | G28: 3일 | H28: 예정
A29: 5 | B29: 개발 단계 (핵심 기능 개발) | C29: 데이터 가공 및 관리 | D29: 이예준 | E29: 11월 20일 | F29: 11월 24일 | G29: 3일 | H29: 예정
A30: 5.1 | C30: Login(로그인) | D30: 박승찬 | E30: 11월 25일 | F30: 12월 9일 | G30: 11일 | H30: 예정
A31: 5.2 | C31: Main(메인페이지) | D31: 주총민 | E31: 12월 01일 | F31: 12월 9일 | G31: 7일 | H31: 예정
A32: 5.3 | C32: Alarm (우측 알림내역) | D32: 주총민 | E32: 12월 01일 | F32: 12월 9일 | G32: 7일 | H32: 예정
A33: 5.4 | C33: Floors(건물 보기 페이지) | D33: 이예준 | E33: 12월 01일 | F33: 12월 9일 | G33: 7일 | H33: 예정
A34: 5.41 | C34: Elevators(승강기 조작페이지) | D34: 이예준 | E34: 12월 01일 | F34: 12월 9일 | G34: 7일 | H34: 예정
A35: 5.42 | C35: FloorControl (층별 조작 페이지) | D35: 이예준 | E35: 12월 01일 | F35: 12월 9일 | G35: 7일 | H35: 예정
A36: 5.51 | C36: ElecData(전력 현황 페이지) | D36: 박승찬 | E36: 12월 01일 | F36: 12월 9일 | G36: 7일 | H36: 예정
A37: 5.52 | C37: GasData(가스 현황 페이지) | D37: 박승찬 | E37: 12월 01일 | F37: 12월 9일 | G37: 7일 | H37: 예정
A38: 5.53 | C38: WaterData (수도 현황 페이지) | D38: 박승찬 | E38: 12월 01일 | F38: 12월 9일 | G38: 7일 | H38: 예정
A39: 5.54 | C39: TempData (온도 현황 페이지) | D39: 박승찬 | E39: 12월 01일 | F39: 12월 9일 | G39: 7일 | H39: 예정
A40: 5.6 | C40: Problems(문제 내역 페이지) | D40: 전서영 | E40: 11월 20일 | F40: 11월 28일 | G40: 7일 | H40: 예정
...

Sheet Sheet2
B2: 휴일 | C2: 내용
B3: 45658 | C3: 신정
B4: 45685 | C4: 명절
B5: 45686 | C5: 설날 연휴 | N5: 1개월
B6: 45687 | C6: 설날 연휴 | N6: 1개월
B7: 45717 | C7: 3·1절 | N7: 1개월
B8: 45719 | C8: 3.1절대체휴일 | N8: 1개월
B9: 45778 | C9: 근로자의날 | N9: 1개월
B10: 45779 | C10: 징검다리 | N10: 1개월
B11: 45782 | C11: 어린이날 | N11: 1개월
B12: 45783 | C12: 대체휴일 | N12: 1개월
B13: 45814 | C13: 현충일 | N13: 1개월
B14: 45884 | C14: 광복절 | N14: 0.5개월
B15: 45936 | C15: 명절 | N15: 0.5개월
B16: 45937 | C16: 추석 | N16: 0.5개월
... B25: 46083 | C25: 대체 | N25: 1개월
N26: 1개월
N27: 1개월
N28: 1개월
N29: 1개월
N30: 1개월
N31: 지속
N32: 지속
N33: 지속
N34: 1개월
N35: 1개월
